
<robot name="Hound_description" xmlns:xacro="http://www.ros.org/wiki/xacro">
  <material name="black">
    <color rgba="0.0 0.0 0.0 1.0"/>
  </material>
  <material name="blue">
    <color rgba="0.0 0.0 0.8 1.0"/>
  </material>
  <material name="green">
    <color rgba="0.0 0.8 0.0 1.0"/>
  </material>
  <material name="grey">
    <color rgba="0.2 0.2 0.2 1.0"/>
  </material>
  <material name="silver">
    <color rgba="0.913725490196 0.913725490196 0.847058823529 1.0"/>
  </material>
  <material name="orange">
    <color rgba="1.0 0.423529411765 0.0392156862745 1.0"/>
  </material>
  <material name="brown">
    <color rgba="0.870588235294 0.811764705882 0.764705882353 1.0"/>
  </material>
  <material name="red">
    <color rgba="0.8 0.0 0.0 1.0"/>
  </material>
  <material name="white">
    <color rgba="1.0 1.0 1.0 1.0"/>
  </material>

  <link name="trunk">
    <visual>
      <origin rpy="0 0 0" xyz="0 0 0"/>
      <geometry>
        <mesh filename="base.stl" scale="1 1 1"/>
      </geometry>
      <material name="silver"/>
    </visual>
    <collision>
      <origin rpy="0 0 0" xyz="0 0 0"/>
      <geometry>
        <box size="0.55800000 0.28000000 0.16400000"/>
      </geometry>
    </collision>
    <inertial>
      <origin rpy="0 0 0" xyz="-0.00407276 0.00141638 0.00481511"/>
      <mass value="26.70000000"/>
      <inertia ixx="0.28785726" ixy="-0.00662284" ixz="-0.00388278" iyy="0.98299330" iyz="0.00122766" izz="1.16936671"/>
    </inertial>
  </link>


  <joint name="RR_roll_joint" type="revolute">
    <origin rpy="0 0 0" xyz="-0.37500000 -0.10000000 0.00000000"/>
    <parent link="trunk"/>
    <child link="RR_shoulder"/>
    <axis xyz="1 0 0"/>
    <dynamics rotor_inertia="0.01323732" damping="0" friction="0"/>
    <limit effort="180.00000000" lower="-0.78539816" upper="0.78539816" velocity="100.00000000"/>
  </joint>
  <link name="RR_shoulder">
    <visual>
      <origin rpy="0 3.141592 0" xyz="0 0 0"/>
      <geometry>
        <mesh filename="shoulder.stl" scale="1 1 1"/>
      </geometry>
      <material name="grey"/>
    </visual>
    <collision>
      <origin rpy="1.57079632679 0 0" xyz="0 -0.01750000 0"/>
      <geometry>
        <cylinder length="0.14500000" radius="0.08100000"/>
      </geometry>
    </collision>
    <inertial>
      <origin rpy="0 0 0" xyz="-0.00707032 0.02389593 -0.00006497"/>
      <mass value="3.97000000"/>
      <inertia ixx="0.00993164" ixy="-0.00033442" ixz="0.00000000" iyy="0.01580543" iyz="-0.00000000" izz="0.01211113"/>
    </inertial>
  </link>
  <joint name="RR_hip_joint" type="revolute">
    <origin rpy="0 0 0" xyz="0 -0.12860000 0"/>
    <parent link="RR_shoulder"/>
    <child link="RR_thigh"/>
    <axis xyz="0 1 0"/>
    <dynamics rotor_inertia="0.03330373" damping="0" friction="0"/>
    <limit effort="180.00000000" lower="-6.28318531" upper="6.28318531" velocity="100.00000000"/>
  </joint>
  <link name="RR_thigh">
    <visual>
      <origin rpy="0 0 0" xyz="0 0 0"/>
      <geometry>
        <mesh filename="thigh.stl" scale="1 1 1"/>
      </geometry>
      <material name="grey"/>
    </visual>
    <collision>
      <origin rpy="0 0 0" xyz="0 0 -0.17425000"/>
      <geometry>
        <box size="0.07800000 0.06900000 0.42100000"/>
      </geometry>
    </collision>
    <inertial>
      <origin rpy="0 0 0" xyz="0.00000000 0.06122941 -0.09740008"/>
      <mass value="1.54800000"/>
      <inertia ixx="0.02517926" ixy="0.00000000" ixz="0.00000000" iyy="0.02442722" iyz="-0.00415327" izz="0.00333936"/>
    </inertial>
  </link>

  <joint name="RR_knee_joint" type="revolute">
    <origin rpy="0 0 0" xyz="0 0 -0.34850000"/>
    <parent link="RR_thigh"/>
    <child link="RR_calf"/>
    <axis xyz="0 1 0"/>
    <dynamics rotor_inertia="0.03187804" damping="0" friction="0"/>
    <limit effort="180.00000000" lower="-2.61799388" upper="2.61799388" velocity="100.00000000"/>
  </joint>
  <link name="RR_calf">
    <visual>
      <origin rpy="0 0 0" xyz="0 0 0"/>
      <geometry>
        <mesh filename="calf.stl" scale="1 1 1"/>
      </geometry>
      <material name="silver"/>
    </visual>
    <collision>
      <origin rpy="0 0 0" xyz="0 0 -0.20400000"/>
      <geometry>
        <cylinder length="0.29300000" radius="0.02500000"/>
      </geometry>
    </collision>
    <inertial>
      <origin rpy="0 0 0" xyz="0.00000000 0.00000000 -0.10949417"/>
      <mass value="0.70876911"/>
      <inertia ixx="0.01174540" ixy="0.00000000" ixz="0.00012760" iyy="0.01152561" iyz="0.00000000" izz="0.00054020"/>
    </inertial>
  </link>
  <joint name="RR_foot_fixed" type="fixed">
    <origin rpy="0 0 0" xyz="0 0 -0.35050000"/>
    <parent link="RR_calf"/>
    <child link="RR_foot"/>
  </joint>
  <link name="RR_foot">
<!--
    <visual>
      <origin rpy="0 0 0" xyz="0 0 0"/>
      <geometry>
        <sphere radius="0.04100000"/>
      </geometry>
    </visual>
-->
    <collision>
      <origin rpy="0 0 0" xyz="0 0 0"/>
      <geometry>
        <sphere radius="0.04100000"/>
      </geometry>
    </collision>
    <inertial>
      <origin rpy="0 0 0" xyz="0 0 0"/>
      <mass value="0.01"/>
      <inertia ixx="0.000001" ixy="0.0" ixz="-0.0" iyy="0.000001" iyz="-0.0" izz="0.000001"/>
    </inertial>
  </link>

	
  <joint name="RL_roll_joint" type="revolute">
    <origin rpy="0 0 0" xyz="-0.37500000 0.10000000 0.00000000"/>
    <parent link="trunk"/>
    <child link="RL_shoulder"/>
    <axis xyz="1 0 0"/>
    <dynamics rotor_inertia="0.01323732" damping="0" friction="0"/>
    <limit effort="180.00000000" lower="-0.78539816" upper="0.78539816" velocity="100.00000000"/>
  </joint>
  <link name="RL_shoulder">
    <visual>
      <origin rpy="0 0 3.141592" xyz="0 0 0"/>
      <geometry>
        <mesh filename="shoulder.stl" scale="1 1 1"/>
      </geometry>
      <material name="grey"/>
    </visual>
    <collision>
      <origin rpy="1.57079632679 0 0" xyz="0 0.01750000 0"/>
      <geometry>
        <cylinder length="0.14500000" radius="0.08100000"/>
      </geometry>
    </collision>
    <inertial>
      <origin rpy="0 0 0" xyz="-0.00707032 -0.02389593 0.00006497"/>
      <mass value="3.97000000"/>
      <inertia ixx="0.00993164" ixy="0.00033442" ixz="-0.00000000" iyy="0.01580543" iyz="-0.00000000" izz="0.01211113"/>
    </inertial>
  </link>
  <joint name="RL_hip_joint" type="revolute">
    <origin rpy="0 0 0" xyz="0 0.12860000 0"/>
    <parent link="RL_shoulder"/>
    <child link="RL_thigh"/>
    <axis xyz="0 1 0"/>
    <dynamics rotor_inertia="0.03330373" damping="0" friction="0"/>
    <limit effort="180.00000000" lower="-6.28318531" upper="6.28318531" velocity="100.00000000"/>
  </joint>
  <link name="RL_thigh">
    <visual>
      <origin rpy="0 0 3.141592" xyz="0 0 0"/>
      <geometry>
        <mesh filename="thigh.stl" scale="1 1 1"/>
      </geometry>
      <material name="grey"/>
    </visual>
    <collision>
      <origin rpy="0 0 0" xyz="0 0 -0.17425000"/>
      <geometry>
        <box size="0.07800000 0.06900000 0.42100000"/>
      </geometry>
    </collision>
    <inertial>
      <origin rpy="0 0 0" xyz="-0.00000000 -0.06122941 -0.09740008"/>
      <mass value="1.54800000"/>
      <inertia ixx="0.02517926" ixy="0.00000000" ixz="-0.00000000" iyy="0.02442722" iyz="0.00415327" izz="0.00333936"/>
    </inertial>
  </link>
  <joint name="RL_knee_joint" type="revolute">
    <origin rpy="0 0 0" xyz="0 0 -0.34850000"/>
    <parent link="RL_thigh"/>
    <child link="RL_calf"/>
    <axis xyz="0 1 0"/>
    <dynamics rotor_inertia="0.03187804" damping="0" friction="0"/>
    <limit effort="180.00000000" lower="-2.61799388" upper="2.61799388" velocity="100.00000000"/>
  </joint>
  <link name="RL_calf">
    <visual>
      <origin rpy="0 0 0" xyz="0 0 0"/>
      <geometry>
        <mesh filename="calf.stl" scale="1 1 1"/>
      </geometry>
      <material name="silver"/>
    </visual>
    <collision>
      <origin rpy="0 0 0" xyz="0 0 -0.20400000"/>
      <geometry>
        <cylinder length="0.29300000" radius="0.02500000"/>
      </geometry>
    </collision>
    <inertial>
      <origin rpy="0 0 0" xyz="0.00000000 -0.00000000 -0.10949417"/>
      <mass value="0.70876911"/>
      <inertia ixx="0.01174540" ixy="-0.00000000" ixz="0.00012760" iyy="0.01152561" iyz="-0.00000000" izz="0.00054020"/>
    </inertial>
  </link>
  <joint name="RL_foot_fixed" type="fixed">
    <origin rpy="0 0 0" xyz="0 0 -0.35050000"/>
    <parent link="RL_calf"/>
    <child link="RL_foot"/>
  </joint>
  <link name="RL_foot">
<!--
    <visual>
      <origin rpy="0 0 0" xyz="0 0 0"/>
      <geometry>
        <sphere radius="0.04100000"/>
      </geometry>
    </visual>
-->
    <collision>
      <origin rpy="0 0 0" xyz="0 0 0"/>
      <geometry>
        <sphere radius="0.04100000"/>
      </geometry>
    </collision>
    <inertial>
      <origin rpy="0 0 0" xyz="0 0 0"/>
      <mass value="0.01"/>
      <inertia ixx="0.000001" ixy="0.0" ixz="-0.0" iyy="0.000001" iyz="-0.0" izz="0.000001"/>
    </inertial>
  </link>


  <joint name="FR_roll_joint" type="revolute">
    <origin rpy="0 0 0" xyz="0.37500000 -0.10000000 0.00000000"/>
    <parent link="trunk"/>
    <child link="FR_shoulder"/>
    <axis xyz="1 0 0"/>
    <dynamics rotor_inertia="0.01323732" damping="0" friction="0"/>
    <limit effort="180.00000000" lower="-0.78539816" upper="0.78539816" velocity="100.00000000"/>
  </joint>
  <link name="FR_shoulder">
    <visual>
      <origin rpy="0 0 0" xyz="0 0 0"/>
      <geometry>
        <mesh filename="shoulder.stl" scale="1 1 1"/>
      </geometry>
      <material name="grey"/>
    </visual>
    <collision>
      <origin rpy="1.57079632679 0 0" xyz="0 -0.01750000 0"/>
      <geometry>
        <cylinder length="0.14500000" radius="0.08100000"/>
      </geometry>
    </collision>
    <inertial>
      <origin rpy="0 0 0" xyz="0.00707032 0.02389593 0.00006497"/>
      <mass value="3.97000000"/>
      <inertia ixx="0.00993164" ixy="0.00033442" ixz="0.00000000" iyy="0.01580543" iyz="0.00000000" izz="0.01211113"/>
    </inertial>
  </link>
  <joint name="FR_hip_joint" type="revolute">
    <origin rpy="0 0 0" xyz="0 -0.12860000 0"/>
    <parent link="FR_shoulder"/>
    <child link="FR_thigh"/>
    <axis xyz="0 1 0"/>
    <dynamics rotor_inertia="0.03330373" damping="0" friction="0"/>
    <limit effort="180.00000000" lower="-6.28318531" upper="6.28318531" velocity="100.00000000"/>
  </joint>
  <link name="FR_thigh">
    <visual>
      <origin rpy="0 0 0" xyz="0 0 0"/>
      <geometry>
        <mesh filename="thigh.stl" scale="1 1 1"/>
      </geometry>
      <material name="grey"/>
    </visual>
    <collision>
      <origin rpy="0 0 0" xyz="0 0 -0.17425000"/>
      <geometry>
        <box size="0.07800000 0.06900000 0.42100000"/>
      </geometry>
    </collision>
    <inertial>
      <origin rpy="0 0 0" xyz="0.00000000 0.06122941 -0.09740008"/>
      <mass value="1.54800000"/>
      <inertia ixx="0.02517926" ixy="0.00000000" ixz="0.00000000" iyy="0.02442722" iyz="-0.00415327" izz="0.00333936"/>
    </inertial>
  </link>
  <joint name="FR_knee_joint" type="revolute">
    <origin rpy="0 0 0" xyz="0 0 -0.34850000"/>
    <parent link="FR_thigh"/>
    <child link="FR_calf"/>
    <axis xyz="0 1 0"/>
    <dynamics rotor_inertia="0.03187804" damping="0" friction="0"/>
    <limit effort="180.00000000" lower="-2.61799388" upper="2.61799388" velocity="100.00000000"/>
  </joint>
  <link name="FR_calf">
    <visual>
      <origin rpy="0 0 0" xyz="0 0 0"/>
      <geometry>
        <mesh filename="calf.stl" scale="1 1 1"/>
      </geometry>
      <material name="silver"/>
    </visual>
    <collision>
      <origin rpy="0 0 0" xyz="0 0 -0.20400000"/>
      <geometry>
        <cylinder length="0.29300000" radius="0.02500000"/>
      </geometry>
    </collision>
    <inertial>
      <origin rpy="0 0 0" xyz="0.00000000 0.00000000 -0.10949417"/>
      <mass value="0.70876911"/>
      <inertia ixx="0.01174540" ixy="0.00000000" ixz="0.00012760" iyy="0.01152561" iyz="0.00000000" izz="0.00054020"/>
    </inertial>
  </link>
  <joint name="FR_foot_fixed" type="fixed">
    <origin rpy="0 0 0" xyz="0 0 -0.35050000"/>
    <parent link="FR_calf"/>
    <child link="FR_foot"/>
  </joint>
  <link name="FR_foot">
<!--
    <visual>
      <origin rpy="0 0 0" xyz="0 0 0"/>
      <geometry>
        <sphere radius="0.04100000"/>
      </geometry>
    </visual>
-->
    <collision>
      <origin rpy="0 0 0" xyz="0 0 0"/>
      <geometry>
        <sphere radius="0.04100000"/>
      </geometry>
    </collision>
    <inertial>
      <origin rpy="0 0 0" xyz="0 0 0"/>
      <mass value="0.01"/>
      <inertia ixx="0.000001" ixy="0.0" ixz="-0.0" iyy="0.000001" iyz="-0.0" izz="0.000001"/>
    </inertial>
  </link>


  <joint name="FL_roll_joint" type="revolute">
    <origin rpy="0 0 0" xyz="0.37500000 0.10000000 0.00000000"/>
    <parent link="trunk"/>
    <child link="FL_shoulder"/>
    <axis xyz="1 0 0"/>
    <dynamics rotor_inertia="0.01323732" damping="0" friction="0"/>
    <limit effort="180.00000000" lower="-0.78539816" upper="0.78539816" velocity="100.00000000"/>
  </joint>
  <link name="FL_shoulder">
    <visual>
      <origin rpy="3.141592 0 0" xyz="0 0 0"/>
      <geometry>
        <mesh filename="shoulder.stl" scale="1 1 1"/>
      </geometry>
      <material name="grey"/>
    </visual>
    <collision>
      <origin rpy="1.57079632679 0 0" xyz="0 0.01750000 0"/>
      <geometry>
        <cylinder length="0.14500000" radius="0.08100000"/>
      </geometry>
    </collision>
    <inertial>
      <origin rpy="0 0 0" xyz="0.00707032 -0.02389593 -0.00006497"/>
      <mass value="3.97000000"/>
      <inertia ixx="0.00993164" ixy="-0.00033442" ixz="-0.00000000" iyy="0.01580543" iyz="0.00000000" izz="0.01211113"/>
    </inertial>
  </link>
  <joint name="FL_hip_joint" type="revolute">
    <origin rpy="0 0 0" xyz="0 0.12860000 0"/>
    <parent link="FL_shoulder"/>
    <child link="FL_thigh"/>
    <axis xyz="0 1 0"/>
    <dynamics rotor_inertia="0.03330373" damping="0" friction="0"/>
    <limit effort="180.00000000" lower="-6.28318531" upper="6.28318531" velocity="100.00000000"/>
  </joint>
  <link name="FL_thigh">
    <visual>
      <origin rpy="0 0 3.141592" xyz="0 0 0"/>
      <geometry>
        <mesh filename="thigh.stl" scale="1 1 1"/>
      </geometry>
      <material name="grey"/>
    </visual>
    <collision>
      <origin rpy="0 0 0" xyz="0 0 -0.17425000"/>
      <geometry>
        <box size="0.07800000 0.06900000 0.42100000"/>
      </geometry>
    </collision>
    <inertial>
      <origin rpy="0 0 0" xyz="-0.00000000 -0.06122941 -0.09740008"/>
      <mass value="1.54800000"/>
      <inertia ixx="0.02517926" ixy="0.00000000" ixz="-0.00000000" iyy="0.02442722" iyz="0.00415327" izz="0.00333936"/>
    </inertial>
  </link>
  <joint name="FL_knee_joint" type="revolute">
    <origin rpy="0 0 0" xyz="0 0 -0.34850000"/>
    <parent link="FL_thigh"/>
    <child link="FL_calf"/>
    <axis xyz="0 1 0"/>
    <dynamics rotor_inertia="0.03187804" damping="0" friction="0"/>
    <limit effort="180.00000000" lower="-2.61799388" upper="2.61799388" velocity="100.00000000"/>
  </joint>
  <link name="FL_calf">
    <visual>
      <origin rpy="0 0 0" xyz="0 0 0"/>
      <geometry>
        <mesh filename="calf.stl" scale="1 1 1"/>
      </geometry>
      <material name="silver"/>
    </visual>
    <collision>
      <origin rpy="0 0 0" xyz="0 0 -0.20400000"/>
      <geometry>
        <cylinder length="0.29300000" radius="0.02500000"/>
      </geometry>
    </collision>
    <inertial>
      <origin rpy="0 0 0" xyz="0.00000000 -0.00000000 -0.10949417"/>
      <mass value="0.70876911"/>
      <inertia ixx="0.01174540" ixy="-0.00000000" ixz="0.00012760" iyy="0.01152561" iyz="-0.00000000" izz="0.00054020"/>
    </inertial>
  </link>
  <joint name="FL_foot_fixed" type="fixed">
    <origin rpy="0 0 0" xyz="0 0 -0.35050000"/>
    <parent link="FL_calf"/>
    <child link="FL_foot"/>
  </joint>
  <link name="FL_foot">
<!--
    <visual>
      <origin rpy="0 0 0" xyz="0 0 0"/>
      <geometry>
        <sphere radius="0.04100000"/>
      </geometry>
    </visual>
-->
    <collision>
      <origin rpy="0 0 0" xyz="0 0 0"/>
      <geometry>
        <sphere radius="0.04100000"/>
      </geometry>
    </collision>
    <inertial>
      <origin rpy="0 0 0" xyz="0 0 0"/>
      <mass value="0.01"/>
      <inertia ixx="0.000001" ixy="0.0" ixz="-0.0" iyy="0.000001" iyz="-0.0" izz="0.000001"/>
    </inertial>
  </link>


</robot>

